Workbook

Sheet README
A1: RedLine Medical — User Acceptance Testing (UATD)
A3: Project | B3: RedLine Medical Supplies & Equipment Trading — Odoo ERP Graduation Project
A4: Version / date | B4: 1.0 — 2026-10-25
A5: Target Odoo version | B5: Odoo 19.0 (Enterprise edition assumed)
A6: Business period used for test data | B6: 1 May 2026 – 30 September 2026
A7: IMPORTANT | B7: No test was executed on a live Odoo server. 'Passed (simulated review)' means the expected behaviour was reviewed against the documented scenario and the simulated data (reconciliations in the three data workbooks). Tests depending on Enterprise/optional apps, proposed customizations, security or performance are 'Not Executed - requires live Odoo verification'.
A8: Evidence | B8: Evidence references are simulated cross-references to the data workbooks, not screenshots or logs from Odoo.
A9: Execution / Review Date | B9: Date the simulated review was recorded; blank when not executed.
A10: Defects | B10: No defects were logged because no live execution occurred. The Defect Log sheet is ready for use during real UAT.
A11: Formulas | B11: The Summary sheet counts results with COUNTIF/COUNTIFS.

Sheet Test Cases
A1: Test Case ID | B1: Requirement ID | C1: Module | D1: Scenario | E1: Preconditions | F1: Test Data | G1: Execution Steps | H1: Expected Result | I1: Recorded Result | J1: Pass/Fail Status | K1: Tester | L1: Execution / Review Date | M1: Evidence Reference | N1: Defect ID
A2: TC-001 | B2: CON-001 | C2: Contacts | D2: Create a hospital customer with bilingual name and credit terms | E2: User with Sales role; contact classification tags configured | F2: CUS-001 Al Salam Teaching Hospital / مستشفى السلام التعليمي; terms 30 days; limit EGP 1,000,000 | G2: 1. Contacts > New. 2. Enter English and Arabic names. 3. Set Payment Terms 30 Days and credit limit. 4. Save and open a new quotation for the customer. | H2: Record saved; payment term and credit limit visible; customer selectable on quotation. | I2: Expected behaviour reviewed against the documented scenario and the simulated data; no live Odoo execution. | J2: Passed (simulated review) | K2: Mohamed Essam El-Din Youssef | L2: 46308 | M2: SIM-EVD-001 (simulated data cross-reference) | N2: None
A3: TC-002 | B3: CON-002 | C3: Contacts | D3: Create manufacturer vendor with payment terms | E3: User with Purchase role | F3: VEN-001 Helios Medical Systems GmbH (illustrative); terms 60 days; bank CIB | G3: 1. Contacts > New. 2. Mark as vendor. 3. Set payment term 60 days. 4. Create an RFQ for the vendor. | H3: Vendor saved; RFQ shows vendor and 60-day term. | I3: Expected behaviour reviewed against the documented scenario and the simulated data; no live Odoo execution. | J3: Passed (simulated review) | K3: Mohamed Essam El-Din Youssef | L3: 46308 | M3: SIM-EVD-002 (simulated data cross-reference) | N3: None
A4: TC-003 | B4: CON-003 | C4: Contacts | D4: Duplicate tax-ID warning | E4: Tax ID uniqueness check enabled | F4: Create partner with tax ID TAXID-PLACEHOLDER-001 twice | G4: 1. Create partner with tax ID. 2. Create second partner with the same tax ID. | H4: Second record raises duplicate warning or is blocked. | I4: Not run. Behaviour depends on standard (configuration) / further technical verification; planned for the pilot environment. | J4: Not Executed - requires live Odoo verification | K4: Mohamed Essam El-Din Youssef (planned) | M4: None (no live execution) | N4: None
A5: TC-004 | B5: CON-004 | C5: Contacts | D5: Credit-limit breach on sales confirmation | E5: Customer credit limit set; open receivables exist | F5: CUS-002 limit EGP 2,000,000; confirm an order that pushes exposure above the limit | G5: 1. Create a quotation above available credit. 2. Confirm. | H5: Warning displayed on confirmation; hard block requires the proposed customization. | I5: Not run. Behaviour depends on customization (proposed) / further technical verification; planned for the pilot environment. | J5: Not Executed - requires live Odoo verification | K5: Mohamed Essam El-Din Youssef (planned) | M5: None (no live execution) | N5: None
A6: TC-005 | B6: SAL-001 | C6: Sales | D6: Quotation with contract discount and 14% VAT | E6: Pricelist with 3% discount for CUS-001 | F6: Product EQ-MON-001 qty 2; list price EGP 54,500 | G6: 1. Sales > New quotation for CUS-001. 2. Add product. 3. Check unit price, VAT and print PDF in Arabic. | H6: Unit price = list price less 3%; VAT 14% added; PDF bilingual. | I6: Expected behaviour reviewed against the documented scenario and the simulated data; no live Odoo execution. | J6: Passed (simulated review) | K6: Mohamed Essam El-Din Youssef | L6: 46308 | M6: SIM-EVD-005 (simulated data cross-reference) | N6: None
A7: TC-006 | B7: SAL-002 | C7: Sales | D7: Quotation above EGP 500,000 requires approval | E7: Approval rule configured | F7: Quotation total EGP 1,250,000 for CUS-002 | G7: 1. Create quotation above threshold. 2. Attempt to confirm as sales rep. 3. Approve as Sales Manager. | H7: Confirmation blocked until approval is granted and logged. | I7: Not run. Behaviour depends on customization (proposed) / further technical verification; planned for the pilot environment. | J7: Not Executed - requires live Odoo verification | K7: Mohamed Essam El-Din Youssef (planned) | M7: None (no live execution) | N7: None
A8: TC-007 | B8: SAL-003 | C8: Sales | D8: Order confirmation generates warehouse delivery | E8: Stock available in EQP/CON | F8: SO/2026/0001 (Al Salam Teaching Hospital) | G8: 1. Confirm the sales order. 2. Open generated delivery orders. | H8: One delivery per source warehouse is created with reserved stock. | I8: Expected behaviour reviewed against the documented scenario and the simulated data; no live Odoo execution. | J8: Passed (simulated review) | K8: Mohamed Essam El-Din Youssef | L8: 46308 | M8: SIM-EVD-007 (simulated data cross-reference) | N8: None
A9: TC-008 | B9: SAL-004 | C9: Sales | D9: Partial delivery and backorder | E9: Order with insufficient delivered quantity | F9: SO/2026/0076 — status: Partially Delivered (backorder open) | G9: 1. Open delivery. 2. Set done quantity below demand. 3. Validate and create backorder. 4. Create invoice from delivered quantity. | H9: Backorder created; invoice quantity equals delivered quantity (see Sales Order Lines: ordered > delivered). | I9: Expected behaviour reviewed against the documented scenario and the simulated data; no live Odoo execution. | J9: Passed (simulated review) | K9: Mohamed Essam El-Din Youssef | L9: 46308 | M9: SIM-EVD-008 (simulated data cross-reference) | N9: None
A10: TC-009 | B10: SAL-005 | C10: Sales | D10: Sales analysis by branch | E10: Analytic plan Branch applied | F10: All invoices 1 May 2026 – 30 September 2026; compare branch totals with invoice total EGP 31,077,427 | G10: 1. Open Sales Analysis. 2. Group by Branch. 3. Compare total to invoices. | H10: Branch sub-totals add up to the invoiced net. | I10: Not run. Behaviour depends on standard (configuration) / further technical verification; planned for the pilot environment. | J10: Not Executed - requires live Odoo verification | K10: Mohamed Essam El-Din Youssef (planned) | M10: None (no live execution) | N10: None
A11: TC-010 | B11: SAL-006 | C11: Sales | D11: Contract discount applied by pricelist | E11: Pricelist assigned to CUS-009 (5%) | F11: Product CN-GLV-001 qty 100 | G11: 1. New quotation for CUS-009. 2. Add product. | H11: Price equals list price less 5%. | I11: Expected behaviour reviewed against the documented scenario and the simulated data; no live Odoo execution. | J11: Passed (simulated review) | K11: Mohamed Essam El-Din Youssef | L11: 46308 | M11: SIM-EVD-010 (simulated data cross-reference) | N11: None
A12: TC-011 | B12: SAL-007 | C12: Sales | D12: Warranty end date for delivered serial | E12: Warranty months set on product; serial delivered | F12: Serial SN-AUT-2603-0001 delivered to CUS-011 on 2026-08-20; warranty end 2028-08-20 | G12: 1. Open the serial in Traceability. 2. View warranty end date and status. | H12: Warranty end date = delivery date + warranty months (requires proposed custom field/report). | I12: Not run. Behaviour depends on customization (proposed) / further technical verification; planned for the pilot environment. | J12: Not Executed - requires live Odoo verification | K12: Mohamed Essam El-Din Youssef (planned) | M12: None (no live execution) | N12: None
A13: TC-012 | B13: SAL-008 | C13: Sales | D13: Customer return received into quarantine and credited | E13: Delivered and invoiced order | F13: QRT/RET/0001 on INV/2026/00007: CN-SYR-001 qty 13, reason 'Damaged in transit'; credit note RINV/2026/00001 | G13: 1. Open invoice > Reverse / Return. 2. Receive return in QRT/Quarantine. 3. Post credit note. | H13: Stock enters QRT/Quarantine; credit note reverses revenue and VAT for the returned quantity. | I13: Expected behaviour reviewed against the documented scenario and the simulated data; no live Odoo execution. | J13: Passed (simulated review) | K13: Mohamed Essam El-Din Youssef | L13: 46308 | M13: SIM-EVD-012 (simulated data cross-reference) | N13: None
A14: TC-013 | B14: SAL-009 | C14: Sales | D14: Retail cash sale at Maadi | E14: Retail customer CUS-013; Maadi cash safe journal CSH2 | F14: SO/2026/0005 invoice INV/2026/00003 total EGP 3,990 | G14: 1. Create order. 2. Deliver. 3. Invoice. 4. Register cash payment in CSH2. | H14: Invoice paid in full on the same day; CSH2 increases. | I14: Expected behaviour reviewed against the documented scenario and the simulated data; no live Odoo execution. | J14: Passed (simulated review) | K14: Mohamed Essam El-Din Youssef | L14: 46308 | M14: SIM-EVD-013 (simulated data cross-reference) | N14: None
A15: TC-014 | B15: PUR-001 | C15: Purchase | D15: RFQ converted to PO | E15: Vendor and products exist | F15: PO/2026/0001 to Helios Medical Systems GmbH for warehouse EQP | G15: 1. Create RFQ. 2. Confirm order. 3. Check receipt. | H15: PO confirmed; receipt created for warehouse with expected date. | I15: Expected behaviour reviewed against the documented scenario and the simulated data; no live Odoo execution. | J15: Passed (simulated review) | K15: Fathy Adel Fathy | L15: 46308 | M15: SIM-EVD-014 (simulated data cross-reference) | N15: None
A16: TC-015 | B16: PUR-002 | C16: Purchase | D16: PO above EGP 250,000 requires approval | E16: Double validation threshold configured | F16: MRI purchase PO/2026/0007 total EGP 18,500,000 | G16: 1. Create PO above threshold. 2. Confirm as buyer. 3. Approve as manager. | H16: State = To Approve until approved. | I16: Expected behaviour reviewed against the documented scenario and the simulated data; no live Odoo execution. | J16: Passed (simulated review) | K16: Fathy Adel Fathy | L16: 46308 | M16: SIM-EVD-015 (simulated data cross-reference) | N16: None
A17: TC-016 | B17: PUR-003 | C17: Purchase | D17: Scheduler creates RFQs from reordering rules | E17: Reordering rules defined; stock below minimum | F17: First replenishment PO in period: PO/2026/0001 (2026-05-17) | G17: 1. Inventory > Operations > Replenishment. 2. Run scheduler. 3. Review generated RFQs. | H17: RFQs created per vendor up to max quantity. | I17: Expected behaviour reviewed against the documented scenario and the simulated data; no live Odoo execution. | J17: Passed (simulated review) | K17: Fathy Adel Fathy | L17: 46308 | M17: SIM-EVD-016 (simulated data cross-reference) | N17: None
A18: TC-017 | B18: PUR-004 | C18: Purchase | D18: Bill matched to received quantity | E18: Receipt validated | F18: PO/2026/0004 received CON/IN/00001; bill BILL/2026/00001 | G18: 1. Create bill from PO. 2. Compare billed qty with received qty. | H18: Bill quantities equal received quantities; net EGP 102,828. | I18: Expected behaviour reviewed against the documented scenario and the simulated data; no live Odoo execution. | J18: Passed (simulated review) | K18: Fathy Adel Fathy | L18: 46308 | M18: SIM-EVD-017 (simulated data cross-reference) | N18: None
A19: TC-018 | B19: PUR-005 | C19: Purchase | D19: Supplier return of failed-inspection goods | E19: Failed QC; stock in QRT | F19: QRT/SRET/0001: EQ-SUR-001 lot SN-SUR-2606-0017 qty 1 to Pharos Surgical Supplies | G19: 1. Create return from the bill's receipt. 2. Validate from QRT to vendor. 3. Post debit note. | H19: Payable reduced by debit note; stock leaves QRT. | I19: Expected behaviour reviewed against the documented scenario and the simulated data; no live Odoo execution. | J19: Passed (simulated review) | K19: Fathy Adel Fathy | L19: 46308 | M19: SIM-EVD-018 (simulated data cross-reference) | N19: None
A20: TC-019 | B20: PUR-006 | C20: Purchase | D20: Serial-tracked equipment purchase (MRI) | E20: Capital equipment product tracked by serial | F20: PO/2026/0007: EQ-MRI-001 qty 1 from VEN-002 | G20: 1. Create manual PO. 2. Receive and enter serial number. 3. Confirm quantity 1. | H20: Serial created and linked to receipt; on-hand = 1 in EQP. | I20: Expected behaviour reviewed against the documented scenario and the simulated data; no live Odoo execution. | J20: Passed (simulated review) | K20: Fathy Adel Fathy | L20: 46308 | M20: SIM-EVD-019 (simulated data cross-reference) | N20: None
A21: TC-020 | B21: PUR-007 | C21: Purchase | D21: Consumables purchase with lot and expiry | E21: Product CN-GLV-001 lot + expiry tracked | F21: Receipt of CN-GLV-001 with vendor lot and expiry | G21: 1. Validate receipt. 2. Enter lot and expiry date for each line. | H21: Validation requires lot and expiry; lot appears in Lot register. | I21: Expected behaviour reviewed against the documented scenario and the simulated data; no live Odoo execution. | J21: Passed (simulated review) | K21: Fathy Adel Fathy | L21: 46308 | M21: SIM-EVD-020 (simulated data cross-reference) | N21: None
A22: TC-021 | B22: INV-001 | C22: Inventory | D22: Two-step receipt and putaway | E22: Warehouse CON set to 2-step reception | F22: A receipt for CON | G22: 1. Validate receipt into CON/Input. 2. Process internal putaway to CON/Stock. | H22: Stock available only after putaway. | I22: Expected behaviour reviewed against the documented scenario and the simulated data; no live Odoo execution. | J22: Passed (simulated review) | K22: Ahmed Mahmoud Mohamed | L22: 46308 | M22: SIM-EVD-021 (simulated data cross-reference) | N22: None
A23: TC-022 | B23: INV-002 | C23: Inventory | D23: Failed incoming inspection routed to quarantine | E23: Quality control point on receipts | F23: A receipt line fails QC (see Customer and Supplier Returns: SRET) | G23: 1. Open quality check. 2. Mark Fail. 3. Create transfer to QRT. | H23: Failed units are moved to QRT/Quarantine and blocked from sale (Quality app = Enterprise). | I23: Not run. Behaviour depends on enterprise feature / further technical verification; planned for the pilot environment. | J23: Not Executed - requires live Odoo verification | K23: Ahmed Mahmoud Mohamed (planned) | M23: None (no live execution) | N23: None
A24: TC-023 | B24: INV-003 | C24: Inventory | D24: Lot assignment on receipt | E24: Lot-tracked product | F24: Lot register in Products workbook | G24: 1. Receive lot-tracked product. 2. Assign lot names. | H24: Lot quantities match the register. | I24: Expected behaviour reviewed against the documented scenario and the simulated data; no live Odoo execution. | J24: Passed (simulated review) | K24: Ahmed Mahmoud Mohamed | L24: 46308 | M24: SIM-EVD-023 (simulated data cross-reference) | N24: None
A25: TC-024 | B25: INV-004 | C25: Inventory | D25: Serial numbers on receipt | E25: Serial-tracked product | F25: Serial register entries for EQ-INF-001 | G25: 1. Receive 4 units. 2. Generate/import serials. | H25: Four unique serials; duplicates rejected. | I25: Expected behaviour reviewed against the documented scenario and the simulated data; no live Odoo execution. | J25: Passed (simulated review) | K25: Ahmed Mahmoud Mohamed | L25: 46308 | M25: SIM-EVD-024 (simulated data cross-reference) | N25: None
A26: TC-025 | B26: INV-005 | C26: Inventory | D26: Expiry date shown on lots | E26: Expiration dates enabled | F26: Lot register (expiry column) | G26: 1. Open a lot. 2. Verify expiry, alert and removal dates. | H26: Dates match the Lot and Batch Register. | I26: Expected behaviour reviewed against the documented scenario and the simulated data; no live Odoo execution. | J26: Passed (simulated review) | K26: Ahmed Mahmoud Mohamed | L26: 46308 | M26: SIM-EVD-025 (simulated data cross-reference) | N26: None
A27: TC-026 | B27: INV-006 | C27: Inventory | D27: FEFO picks earliest-expiry lot first | E27: Removal strategy FEFO on category MED-CON | F27: CON/OUT/00010: CN-MSK-001 picked LOT-MSK-2602A1 x171 (exp 2027-03-12); LOT-MSK-2603B2 x326 (exp 2027-08-26) | G27: 1. Reserve the delivery. 2. Compare reserved lots with expiry dates. | H27: Lots reserved in ascending expiry order. | I27: Expected behaviour reviewed against the documented scenario and the simulated data; no live Odoo execution. | J27: Passed (simulated review) | K27: Ahmed Mahmoud Mohamed | L27: 46308 | M27: SIM-EVD-026 (simulated data cross-reference) | N27: None
A28: TC-027 | B28: INV-007 | C28: Inventory | D28: Near-expiry alert and report | E28: Alert time = 60 days | F28: Lot LOT-PAD-2602A1 (CN-PAD-001) expires 2026-11-25 with 20 units in QRT | G28: 1. Run Near-Expiry report. 2. Filter Days to Expiry <= 60. | H28: Flagged lot appears; sale of lots with <60 days is excluded by process. | I28: Not run. Behaviour depends on standard (configuration) / further technical verification; planned for the pilot environment. | J28: Not Executed - requires live Odoo verification | K28: Ahmed Mahmoud Mohamed (planned) | M28: None (no live execution) | N28: None
A29: TC-028 | B29: INV-008 | C29: Inventory | D29: Inter-warehouse transfer without double counting | E29: Two internal warehouses | F29: INT/00002: SP-BAT-001 qty 6 SPR → EQP on 2026-06-15 | G29: 1. Create internal transfer. 2. Validate. | H29: Source decreases, destination increases; company total unchanged. | I29: Expected behaviour reviewed against the documented scenario and the simulated data; no live Odoo execution. | J29: Passed (simulated review) | K29: Ahmed Mahmoud Mohamed | L29: 46308 | M29: SIM-EVD-028 (simulated data cross-reference) | N29: None
A30: TC-029 | B30: INV-009 | C30: Inventory | D30: Quarantine transfer for damaged stock | E30: QRT warehouse configured as non-sellable | F30: SCRAP/0001: CN-SYR-001 lot LOT-SYR-2603A1 | G30: 1. Transfer item to QRT. 2. Try to reserve it on a delivery. | H30: Item not reservable. | I30: Expected behaviour reviewed against the documented scenario and the simulated data; no live Odoo execution. | J30: Passed (simulated review) | K30: Ahmed Mahmoud Mohamed | L30: 46308 | M30: SIM-EVD-029 (simulated data cross-reference) | N30: None
A31: TC-030 | B31: INV-010 | C31: Inventory | D31: Scrap expired lot to expiry-loss account | E31: Scrap reason Expired mapped to 540200 | F31: SCRAP/0003 on 2026-06-30 value EGP 46,000 | G31: 1. Create scrap order. 2. Validate. 3. Open journal entry. | H31: Dr 540200 / Cr inventory 130200 at cost. | I31: Not run. Behaviour depends on standard (configuration) / further technical verification; planned for the pilot environment. | J31: Not Executed - requires live Odoo verification | K31: Ahmed Mahmoud Mohamed (planned) | M31: None (no live execution) | N31: None
A32: TC-031 | B32: INV-011 | C32: Inventory | D32: Cycle-count shortage adjustment | E32: Inventory adjustment enabled | F32: ADJ/2026/0002: Physical count shortage (cycle count) | G32: 1. Inventory > Adjustments. 2. Apply counted quantity. 3. Review entry. | H32: On-hand updated; Dr 540100 / Cr inventory. | I32: Expected behaviour reviewed against the documented scenario and the simulated data; no live Odoo execution. | J32: Passed (simulated review) | K32: Ahmed Mahmoud Mohamed | L32: 46308 | M32: SIM-EVD-031 (simulated data cross-reference) | N32: None
A33: TC-032 | B33: INV-012 | C33: Inventory | D33: Reordering rules loaded | E33: Rules imported | F33: Reordering Rules sheet (24 products; 23 with rules) | G33: 1. Open Reordering Rules. 2. Compare with the sheet. | H33: Rules equal Min/Max/Multiple per product. | I33: Expected behaviour reviewed against the documented scenario and the simulated data; no live Odoo execution. | J33: Passed (simulated review) | K33: Ahmed Mahmoud Mohamed | L33: 46308 | M33: SIM-EVD-032 (simulated data cross-reference) | N33: None
A34: TC-033 | B34: INV-013 | C34: Inventory | D34: Recall trace for a lot / serial | E34: Traceability report enabled | F34: Serial SN-AUT-2603-0001 → customer CUS-011 | G34: 1. Inventory > Traceability. 2. Enter serial. 3. View upstream and downstream. | H34: Report lists vendor receipt and customer delivery. | I34: Expected behaviour reviewed against the documented scenario and the simulated data; no live Odoo execution. | J34: Passed (simulated review) | K34: Ahmed Mahmoud Mohamed | L34: 46308 | M34: SIM-EVD-033 (simulated data cross-reference) | N34: None
A35: TC-034 | B35: INV-014 | C35: Inventory | D35: Pick then ship | E35: 2-step delivery on EQP | F35: Delivery from EQP | G35: 1. Validate pick. 2. Validate ship. | H35: Stock leaves EQP/Output on ship. | I35: Expected behaviour reviewed against the documented scenario and the simulated data; no live Odoo execution. | J35: Passed (simulated review) | K35: Ahmed Mahmoud Mohamed | L35: 46308 | M35: SIM-EVD-034 (simulated data cross-reference) | N35: None
A36: TC-035 | B36: INV-015 | C36: Inventory | D36: Negative stock blocked | E36: Negative quantities disallowed | F36: Deliver 99,999 units of CN-GLV-001 | G36: 1. Reserve. 2. Force validation. | H36: Validation refused; no negative stock. | I36: Expected behaviour reviewed against the documented scenario and the simulated data; no live Odoo execution. | J36: Passed (simulated review) | K36: Ahmed Mahmoud Mohamed | L36: 46308 | M36: SIM-EVD-035 (simulated data cross-reference) | N36: None
A37: TC-036 | B37: INV-016 | C37: Inventory | D37: Barcode scan selects product | E37: Barcode app installed | F37: Barcode 6229990000034 | G37: 1. Open Barcode app. 2. Scan. | H37: Product selected. | I37: Not run. Behaviour depends on optional app / further technical verification; planned for the pilot environment. | J37: Not Executed - requires live Odoo verification | K37: Ahmed Mahmoud Mohamed (planned) | M37: None (no live execution) | N37: None
A38: TC-037 | B38: INV-017 | C38: Inventory | D38: Valuation report equals GL | E38: Automated valuation | F38: Inventory total EGP 24,536,323 at 30-Sep-2026 | G38: 1. Open valuation report. 2. Compare to accounts 1301xx-1303xx. | H38: Totals equal. | I38: Expected behaviour reviewed against the documented scenario and the simulated data; no live Odoo execution. | J38: Passed (simulated review) | K38: Ahmed Mahmoud Mohamed | L38: 46308 | M38: SIM-EVD-037 (simulated data cross-reference) | N38: None
A39: TC-038 | B39: ACC-001 | C39: Accounting | D39: Invoice posting with VAT and branch | E39: Delivered order | F39: INV/2026/00001: net EGP 134,007, VAT EGP 18,761 | G39: 1. Create invoice from order. 2. Post. 3. Review journal entry. | H39: Dr 120100 total; Cr revenue and 220100; branch analytic. | I39: Expected behaviour reviewed against the documented scenario and the simulated data; no live Odoo execution. | J39: Passed (simulated review) | K39: Omnia Haitham | L39: 46308 | M39: SIM-EVD-038 (simulated data cross-reference) | N39: None
A40: TC-039 | B40: ACC-002 | C40: Accounting | D40: Vendor bill posting | E40: Receipt validated | F40: BILL/2026/00001 net EGP 102,828 VAT EGP 14,395 | G40: 1. Create bill. 2. Post. | H40: Dr 210500 and 140300; Cr 210100. | I40: Expected behaviour reviewed against the documented scenario and the simulated data; no live Odoo execution. | J40: Passed (simulated review) | K40: Omnia Haitham | L40: 46308 | M40: SIM-EVD-039 (simulated data cross-reference) | N40: None
...

Sheet Summary
A1: UAT summary (formulas)
A3: Total test cases | B3: =COUNTA('Test Cases'!$A$2:$A$78) -> 77
A4: Passed (simulated review) | B4: =COUNTIF('Test Cases'!$J$2:$J$78,"Passed (simulated review)") -> 50
A5: Failed | B5: =COUNTIF('Test Cases'!$J$2:$J$78,"Failed") -> 0
A6: Not executed - requires live Odoo verification | B6: =COUNTIF('Test Cases'!$J$2:$J$78,"Not Executed*") -> 27
A7: Passed on live Odoo | B7: =COUNTIF('Test Cases'!$J$2:$J$78,"Passed (live Odoo)") -> 0
A8: Distinct requirements covered | B8: =SUMPRODUCT(1/COUNTIF('Test Cases'!$B$2:$B$78,'Test Cases'!$B$2:$B$78)) -> 75
A11: By module
A12: Module | B12: Tests | C12: Passed (simulated) | D12: Not executed
A13: Contacts | B13: =COUNTIF('Test Cases'!$C$2:$C$78,A13) -> 4 | C13: =COUNTIFS('Test Cases'!$C$2:$C$78,A13,'Test Cases'!$J$2:$J$78,"Passed (simulated review)") -> 2 | D13: =COUNTIFS('Test Cases'!$C$2:$C$78,A13,'Test Cases'!$J$2:$J$78,"Not Executed*") -> 2
A14: Sales | B14: =COUNTIF('Test Cases'!$C$2:$C$78,A14) -> 10 | C14: =COUNTIFS('Test Cases'!$C$2:$C$78,A14,'Test Cases'!$J$2:$J$78,"Passed (simulated review)") -> 7 | D14: =COUNTIFS('Test Cases'!$C$2:$C$78,A14,'Test Cases'!$J$2:$J$78,"Not Executed*") -> 3
A15: CRM | B15: =COUNTIF('Test Cases'!$C$2:$C$78,A15) -> 8 | C15: =COUNTIFS('Test Cases'!$C$2:$C$78,A15,'Test Cases'!$J$2:$J$78,"Passed (simulated review)") -> 7 | D15: =COUNTIFS('Test Cases'!$C$2:$C$78,A15,'Test Cases'!$J$2:$J$78,"Not Executed*") -> 1
A16: Purchase | B16: =COUNTIF('Test Cases'!$C$2:$C$78,A16) -> 7 | C16: =COUNTIFS('Test Cases'!$C$2:$C$78,A16,'Test Cases'!$J$2:$J$78,"Passed (simulated review)") -> 7 | D16: =COUNTIFS('Test Cases'!$C$2:$C$78,A16,'Test Cases'!$J$2:$J$78,"Not Executed*") -> 0
A17: Inventory | B17: =COUNTIF('Test Cases'!$C$2:$C$78,A17) -> 18 | C17: =COUNTIFS('Test Cases'!$C$2:$C$78,A17,'Test Cases'!$J$2:$J$78,"Passed (simulated review)") -> 14 | D17: =COUNTIFS('Test Cases'!$C$2:$C$78,A17,'Test Cases'!$J$2:$J$78,"Not Executed*") -> 4
A18: Accounting | B18: =COUNTIF('Test Cases'!$C$2:$C$78,A18) -> 12 | C18: =COUNTIFS('Test Cases'!$C$2:$C$78,A18,'Test Cases'!$J$2:$J$78,"Passed (simulated review)") -> 7 | D18: =COUNTIFS('Test Cases'!$C$2:$C$78,A18,'Test Cases'!$J$2:$J$78,"Not Executed*") -> 5
A19: Reporting | B19: =COUNTIF('Test Cases'!$C$2:$C$78,A19) -> 4 | C19: =COUNTIFS('Test Cases'!$C$2:$C$78,A19,'Test Cases'!$J$2:$J$78,"Passed (simulated review)") -> 3 | D19: =COUNTIFS('Test Cases'!$C$2:$C$78,A19,'Test Cases'!$J$2:$J$78,"Not Executed*") -> 1
A20: Security | B20: =COUNTIF('Test Cases'!$C$2:$C$78,A20) -> 5 | C20: =COUNTIFS('Test Cases'!$C$2:$C$78,A20,'Test Cases'!$J$2:$J$78,"Passed (simulated review)") -> 0 | D20: =COUNTIFS('Test Cases'!$C$2:$C$78,A20,'Test Cases'!$J$2:$J$78,"Not Executed*") -> 5
A21: Non-functional | B21: =COUNTIF('Test Cases'!$C$2:$C$78,A21) -> 4 | C21: =COUNTIFS('Test Cases'!$C$2:$C$78,A21,'Test Cases'!$J$2:$J$78,"Passed (simulated review)") -> 0 | D21: =COUNTIFS('Test Cases'!$C$2:$C$78,A21,'Test Cases'!$J$2:$J$78,"Not Executed*") -> 4
A22: Migration | B22: =COUNTIF('Test Cases'!$C$2:$C$78,A22) -> 5 | C22: =COUNTIFS('Test Cases'!$C$2:$C$78,A22,'Test Cases'!$J$2:$J$78,"Passed (simulated review)") -> 3 | D22: =COUNTIFS('Test Cases'!$C$2:$C$78,A22,'Test Cases'!$J$2:$J$78,"Not Executed*") -> 2
A23: Total | B23: =SUM(B13:B22) -> 77 | C23: =SUM(C13:C22) -> 50 | D23: =SUM(D13:D22) -> 27

Sheet Defect Log
A1: Defect ID | B1: Test Case ID | C1: Description | D1: Severity | E1: Status | F1: Reported By | G1: Reported Date | H1: Resolution
A2: (none) | C2: No defects recorded - no live Odoo execution has taken place.
